<!-- ~/nav_robot_wsp/src/nav_robot_simulation/models/my_robot.urdf -->
<robot name="simple_wheeled_robot">

  <!-- Base link of the robot -->
  <link name="base_link">
    <visual>
      <geometry>
        <box size="0.5 0.5 0.1"/>  <!-- A simple box for the base -->
      </geometry>
      <material>
        <color rgba="0.8 0.1 0.1 1.0"/> <!-- Red color -->
      </material>
    </visual>
    <collision>
      <geometry>
        <box size="0.5 0.5 0.1"/>
      </geometry>
    </collision>
    <inertial>
      <mass value="1.0"/>
      <origin xyz="0 0 0" rpy="0 0 0"/>
      <inertia ixx="0.1" iyy="0.1" izz="0.1" ixy="0" ixz="0" iyz="0"/>
    </inertial>
  </link>

  <!-- Wheel link -->
  <link name="wheel">
    <visual>
      <geometry>
        <cylinder length="0.05" radius="0.1"/> <!-- Wheel shape -->
      </geometry>
      <material>
        <color rgba="0.1 0.1 0.8 1.0"/> <!-- Blue color -->
      </material>
    </visual>
    <collision>
      <geometry>
        <cylinder length="0.05" radius="0.1"/>
      </geometry>
    </collision>
    <inertial>
      <mass value="0.2"/>
      <origin xyz="0 0 0" rpy="0 0 0"/>
      <inertia ixx="0.01" iyy="0.01" izz="0.01" ixy="0" ixz="0" iyz="0"/>
    </inertial>
  </link>

  <!-- Continuous joint between base and wheel -->
  <joint name="wheel_joint" type="continuous">
    <parent link="base_link"/>
    <child link="wheel"/>
    <origin xyz="0.25 0 0" rpy="0 0 0"/> <!-- Positioning the wheel -->
    <axis xyz="0 1 0"/> <!-- Wheel rotates around the y-axis -->
    <limit effort="10.0" velocity="10.0"/>
  </joint>

</robot>

